ERROR:TeleBot:ApiTelegramException occurred, args=('A request to the Telegram API was unsuccessful. Error code: 409 Description: Conflict: terminated by other getUpdates request; make sure that only one bot instance is running',)
Traceback (most recent call last):
  File "/Library/Frameworks/Python.framework/Versions/3.8/lib/python3.8/site-packages/telebot/util.py", line 69, in run
    task(*args, **kwargs)
  File "/Library/Frameworks/Python.framework/Versions/3.8/lib/python3.8/site-packages/telebot/__init__.py", line 285, in __retrieve_updates
    updates = self.get_updates(offset=(self.last_update_id + 1), timeout=timeout)
  File "/Library/Frameworks/Python.framework/Versions/3.8/lib/python3.8/site-packages/telebot/__init__.py", line 255, in get_updates
    json_updates = apihelper.get_updates(self.token, offset, limit, timeout, allowed_updates)
  File "/Library/Frameworks/Python.framework/Versions/3.8/lib/python3.8/site-packages/telebot/apihelper.py", line 241, in get_updates
    return _make_request(token, method_url, params=payload)
  File "/Library/Frameworks/Python.framework/Versions/3.8/lib/python3.8/site-packages/telebot/apihelper.py", line 108, in _make_request
    json_result = _check_result(method_name, result)
  File "/Library/Frameworks/Python.framework/Versions/3.8/lib/python3.8/site-packages/telebot/apihelper.py", line 135, in _check_result
    raise ApiTelegramException(method_name, result, result_json)
telebot.apihelper.ApiTelegramException: A request to the Telegram API was unsuccessful. Error code: 409 Description: Conflict: terminated by other getUpdates request; make sure that only one bot instance is running

ERROR:TeleBot:A request to the Telegram API was unsuccessful. Error code: 409 Description: Conflict: terminated by other getUpdates request; make sure that only one bot instance is running
ERROR:TeleBot:ApiTelegramException occurred, args=('A request to the Telegram API was unsuccessful. Error code: 409 Description: Conflict: terminated by other getUpdates request; make sure that only one bot instance is running',)
Traceback (most recent call last):
  File "/Library/Frameworks/Python.framework/Versions/3.8/lib/python3.8/site-packages/telebot/util.py", line 69, in run
    task(*args, **kwargs)
  File "/Library/Frameworks/Python.framework/Versions/3.8/lib/python3.8/site-packages/telebot/__init__.py", line 285, in __retrieve_updates
    updates = self.get_updates(offset=(self.last_update_id + 1), timeout=timeout)
  File "/Library/Frameworks/Python.framework/Versions/3.8/lib/python3.8/site-packages/telebot/__init__.py", line 255, in get_updates
    json_updates = apihelper.get_updates(self.token, offset, limit, timeout, allowed_updates)
  File "/Library/Frameworks/Python.framework/Versions/3.8/lib/python3.8/site-packages/telebot/apihelper.py", line 241, in get_updates
    return _make_request(token, method_url, params=payload)
  File "/Library/Frameworks/Python.framework/Versions/3.8/lib/python3.8/site-packages/telebot/apihelper.py", line 108, in _make_request
    json_result = _check_result(method_name, result)
  File "/Library/Frameworks/Python.framework/Versions/3.8/lib/python3.8/site-packages/telebot/apihelper.py", line 135, in _check_result
    raise ApiTelegramException(method_name, result, result_json)
telebot.apihelper.ApiTelegramException: A request to the Telegram API was unsuccessful. Error code: 409 Description: Conflict: terminated by other getUpdates request; make sure that only one bot instance is running

ERROR:TeleBot:A request to the Telegram API was unsuccessful. Error code: 409 Description: Conflict: terminated by other getUpdates request; make sure that only one bot instance is running
ERROR:TeleBot:ApiTelegramException occurred, args=('A request to the Telegram API was unsuccessful. Error code: 409 Description: Conflict: terminated by other getUpdates request; make sure that only one bot instance is running',)
Traceback (most recent call last):
  File "/Library/Frameworks/Python.framework/Versions/3.8/lib/python3.8/site-packages/telebot/util.py", line 69, in run
    task(*args, **kwargs)
  File "/Library/Frameworks/Python.framework/Versions/3.8/lib/python3.8/site-packages/telebot/__init__.py", line 285, in __retrieve_updates
    updates = self.get_updates(offset=(self.last_update_id + 1), timeout=timeout)
  File "/Library/Frameworks/Python.framework/Versions/3.8/lib/python3.8/site-packages/telebot/__init__.py", line 255, in get_updates
    json_updates = apihelper.get_updates(self.token, offset, limit, timeout, allowed_updates)
  File "/Library/Frameworks/Python.framework/Versions/3.8/lib/python3.8/site-packages/telebot/apihelper.py", line 241, in get_updates
    return _make_request(token, method_url, params=payload)
  File "/Library/Frameworks/Python.framework/Versions/3.8/lib/python3.8/site-packages/telebot/apihelper.py", line 108, in _make_request
    json_result = _check_result(method_name, result)
  File "/Library/Frameworks/Python.framework/Versions/3.8/lib/python3.8/site-packages/telebot/apihelper.py", line 135, in _check_result
    raise ApiTelegramException(method_name, result, result_json)
telebot.apihelper.ApiTelegramException: A request to the Telegram API was unsuccessful. Error code: 409 Description: Conflict: terminated by other getUpdates request; make sure that only one bot instance is running

ERROR:TeleBot:A request to the Telegram API was unsuccessful. Error code: 409 Description: Conflict: terminated by other getUpdates request; make sure that only one bot instance is running
ERROR:TeleBot:ApiTelegramException occurred, args=('A request to the Telegram API was unsuccessful. Error code: 409 Description: Conflict: terminated by other getUpdates request; make sure that only one bot instance is running',)
Traceback (most recent call last):
  File "/Library/Frameworks/Python.framework/Versions/3.8/lib/python3.8/site-packages/telebot/util.py", line 69, in run
    task(*args, **kwargs)
  File "/Library/Frameworks/Python.framework/Versions/3.8/lib/python3.8/site-packages/telebot/__init__.py", line 285, in __retrieve_updates
    updates = self.get_updates(offset=(self.last_update_id + 1), timeout=timeout)
  File "/Library/Frameworks/Python.framework/Versions/3.8/lib/python3.8/site-packages/telebot/__init__.py", line 255, in get_updates
    json_updates = apihelper.get_updates(self.token, offset, limit, timeout, allowed_updates)
  File "/Library/Frameworks/Python.framework/Versions/3.8/lib/python3.8/site-packages/telebot/apihelper.py", line 241, in get_updates
    return _make_request(token, method_url, params=payload)
  File "/Library/Frameworks/Python.framework/Versions/3.8/lib/python3.8/site-packages/telebot/apihelper.py", line 108, in _make_request
    json_result = _check_result(method_name, result)
  File "/Library/Frameworks/Python.framework/Versions/3.8/lib/python3.8/site-packages/telebot/apihelper.py", line 135, in _check_result
    raise ApiTelegramException(method_name, result, result_json)
telebot.apihelper.ApiTelegramException: A request to the Telegram API was unsuccessful. Error code: 409 Description: Conflict: terminated by other getUpdates request; make sure that only one bot instance is running

ERROR:TeleBot:A request to the Telegram API was unsuccessful. Error code: 409 Description: Conflict: terminated by other getUpdates request; make sure that only one bot instance is running
ERROR:TeleBot:ApiTelegramException occurred, args=('A request to the Telegram API was unsuccessful. Error code: 409 Description: Conflict: terminated by other getUpdates request; make sure that only one bot instance is running',)
Traceback (most recent call last):
  File "/Library/Frameworks/Python.framework/Versions/3.8/lib/python3.8/site-packages/telebot/util.py", line 69, in run
    task(*args, **kwargs)
  File "/Library/Frameworks/Python.framework/Versions/3.8/lib/python3.8/site-packages/telebot/__init__.py", line 285, in __retrieve_updates
    updates = self.get_updates(offset=(self.last_update_id + 1), timeout=timeout)
  File "/Library/Frameworks/Python.framework/Versions/3.8/lib/python3.8/site-packages/telebot/__init__.py", line 255, in get_updates
    json_updates = apihelper.get_updates(self.token, offset, limit, timeout, allowed_updates)
  File "/Library/Frameworks/Python.framework/Versions/3.8/lib/python3.8/site-packages/telebot/apihelper.py", line 241, in get_updates
    return _make_request(token, method_url, params=payload)
  File "/Library/Frameworks/Python.framework/Versions/3.8/lib/python3.8/site-packages/telebot/apihelper.py", line 108, in _make_request
    json_result = _check_result(method_name, result)
  File "/Library/Frameworks/Python.framework/Versions/3.8/lib/python3.8/site-packages/telebot/apihelper.py", line 135, in _check_result
    raise ApiTelegramException(method_name, result, result_json)
telebot.apihelper.ApiTelegramException: A request to the Telegram API was unsuccessful. Error code: 409 Description: Conflict: terminated by other getUpdates request; make sure that only one bot instance is running

ERROR:TeleBot:A request to the Telegram API was unsuccessful. Error code: 409 Description: Conflict: terminated by other getUpdates request; make sure that only one bot instance is running
ERROR:TeleBot:ApiTelegramException occurred, args=('A request to the Telegram API was unsuccessful. Error code: 409 Description: Conflict: terminated by other getUpdates request; make sure that only one bot instance is running',)
Traceback (most recent call last):
  File "/Library/Frameworks/Python.framework/Versions/3.8/lib/python3.8/site-packages/telebot/util.py", line 69, in run
    task(*args, **kwargs)
  File "/Library/Frameworks/Python.framework/Versions/3.8/lib/python3.8/site-packages/telebot/__init__.py", line 285, in __retrieve_updates
    updates = self.get_updates(offset=(self.last_update_id + 1), timeout=timeout)
  File "/Library/Frameworks/Python.framework/Versions/3.8/lib/python3.8/site-packages/telebot/__init__.py", line 255, in get_updates
    json_updates = apihelper.get_updates(self.token, offset, limit, timeout, allowed_updates)
  File "/Library/Frameworks/Python.framework/Versions/3.8/lib/python3.8/site-packages/telebot/apihelper.py", line 241, in get_updates
    return _make_request(token, method_url, params=payload)
  File "/Library/Frameworks/Python.framework/Versions/3.8/lib/python3.8/site-packages/telebot/apihelper.py", line 108, in _make_request
    json_result = _check_result(method_name, result)
  File "/Library/Frameworks/Python.framework/Versions/3.8/lib/python3.8/site-packages/telebot/apihelper.py", line 135, in _check_result
    raise ApiTelegramException(method_name, result, result_json)
telebot.apihelper.ApiTelegramException: A request to the Telegram API was unsuccessful. Error code: 409 Description: Conflict: terminated by other getUpdates request; make sure that only one bot instance is running

ERROR:TeleBot:A request to the Telegram API was unsuccessful. Error code: 409 Description: Conflict: terminated by other getUpdates request; make sure that only one bot instance is running
ERROR:TeleBot:ApiTelegramException occurred, args=('A request to the Telegram API was unsuccessful. Error code: 409 Description: Conflict: terminated by other getUpdates request; make sure that only one bot instance is running',)
Traceback (most recent call last):
  File "/Library/Frameworks/Python.framework/Versions/3.8/lib/python3.8/site-packages/telebot/util.py", line 69, in run
    task(*args, **kwargs)
  File "/Library/Frameworks/Python.framework/Versions/3.8/lib/python3.8/site-packages/telebot/__init__.py", line 285, in __retrieve_updates
    updates = self.get_updates(offset=(self.last_update_id + 1), timeout=timeout)
  File "/Library/Frameworks/Python.framework/Versions/3.8/lib/python3.8/site-packages/telebot/__init__.py", line 255, in get_updates
    json_updates = apihelper.get_updates(self.token, offset, limit, timeout, allowed_updates)
  File "/Library/Frameworks/Python.framework/Versions/3.8/lib/python3.8/site-packages/telebot/apihelper.py", line 241, in get_updates
    return _make_request(token, method_url, params=payload)
  File "/Library/Frameworks/Python.framework/Versions/3.8/lib/python3.8/site-packages/telebot/apihelper.py", line 108, in _make_request
    json_result = _check_result(method_name, result)
  File "/Library/Frameworks/Python.framework/Versions/3.8/lib/python3.8/site-packages/telebot/apihelper.py", line 135, in _check_result
    raise ApiTelegramException(method_name, result, result_json)
telebot.apihelper.ApiTelegramException: A request to the Telegram API was unsuccessful. Error code: 409 Description: Conflict: terminated by other getUpdates request; make sure that only one bot instance is running

ERROR:TeleBot:A request to the Telegram API was unsuccessful. Error code: 409 Description: Conflict: terminated by other getUpdates request; make sure that only one bot instance is running
ERROR:TeleBot:ApiTelegramException occurred, args=('A request to the Telegram API was unsuccessful. Error code: 409 Description: Conflict: terminated by other getUpdates request; make sure that only one bot instance is running',)
Traceback (most recent call last):
  File "/Library/Frameworks/Python.framework/Versions/3.8/lib/python3.8/site-packages/telebot/util.py", line 69, in run
    task(*args, **kwargs)
  File "/Library/Frameworks/Python.framework/Versions/3.8/lib/python3.8/site-packages/telebot/__init__.py", line 285, in __retrieve_updates
    updates = self.get_updates(offset=(self.last_update_id + 1), timeout=timeout)
  File "/Library/Frameworks/Python.framework/Versions/3.8/lib/python3.8/site-packages/telebot/__init__.py", line 255, in get_updates
    json_updates = apihelper.get_updates(self.token, offset, limit, timeout, allowed_updates)
  File "/Library/Frameworks/Python.framework/Versions/3.8/lib/python3.8/site-packages/telebot/apihelper.py", line 241, in get_updates
    return _make_request(token, method_url, params=payload)
  File "/Library/Frameworks/Python.framework/Versions/3.8/lib/python3.8/site-packages/telebot/apihelper.py", line 108, in _make_request
    json_result = _check_result(method_name, result)
  File "/Library/Frameworks/Python.framework/Versions/3.8/lib/python3.8/site-packages/telebot/apihelper.py", line 135, in _check_result
    raise ApiTelegramException(method_name, result, result_json)
telebot.apihelper.ApiTelegramException: A request to the Telegram API was unsuccessful. Error code: 409 Description: Conflict: terminated by other getUpdates request; make sure that only one bot instance is running

ERROR:TeleBot:A request to the Telegram API was unsuccessful. Error code: 409 Description: Conflict: terminated by other getUpdates request; make sure that only one bot instance is running
ERROR:TeleBot:ApiTelegramException occurred, args=('A request to the Telegram API was unsuccessful. Error code: 409 Description: Conflict: terminated by other getUpdates request; make sure that only one bot instance is running',)
Traceback (most recent call last):
  File "/Library/Frameworks/Python.framework/Versions/3.8/lib/python3.8/site-packages/telebot/util.py", line 69, in run
    task(*args, **kwargs)
  File "/Library/Frameworks/Python.framework/Versions/3.8/lib/python3.8/site-packages/telebot/__init__.py", line 285, in __retrieve_updates
    updates = self.get_updates(offset=(self.last_update_id + 1), timeout=timeout)
  File "/Library/Frameworks/Python.framework/Versions/3.8/lib/python3.8/site-packages/telebot/__init__.py", line 255, in get_updates
    json_updates = apihelper.get_updates(self.token, offset, limit, timeout, allowed_updates)
  File "/Library/Frameworks/Python.framework/Versions/3.8/lib/python3.8/site-packages/telebot/apihelper.py", line 241, in get_updates
    return _make_request(token, method_url, params=payload)
  File "/Library/Frameworks/Python.framework/Versions/3.8/lib/python3.8/site-packages/telebot/apihelper.py", line 108, in _make_request
    json_result = _check_result(method_name, result)
  File "/Library/Frameworks/Python.framework/Versions/3.8/lib/python3.8/site-packages/telebot/apihelper.py", line 135, in _check_result
    raise ApiTelegramException(method_name, result, result_json)
telebot.apihelper.ApiTelegramException: A request to the Telegram API was unsuccessful. Error code: 409 Description: Conflict: terminated by other getUpdates request; make sure that only one bot instance is running

ERROR:TeleBot:A request to the Telegram API was unsuccessful. Error code: 409 Description: Conflict: terminated by other getUpdates request; make sure that only one bot instance is running
ERROR:TeleBot:ApiTelegramException occurred, args=('A request to the Telegram API was unsuccessful. Error code: 409 Description: Conflict: terminated by other getUpdates request; make sure that only one bot instance is running',)
Traceback (most recent call last):
  File "/Library/Frameworks/Python.framework/Versions/3.8/lib/python3.8/site-packages/telebot/util.py", line 69, in run
    task(*args, **kwargs)
  File "/Library/Frameworks/Python.framework/Versions/3.8/lib/python3.8/site-packages/telebot/__init__.py", line 285, in __retrieve_updates
    updates = self.get_updates(offset=(self.last_update_id + 1), timeout=timeout)
  File "/Library/Frameworks/Python.framework/Versions/3.8/lib/python3.8/site-packages/telebot/__init__.py", line 255, in get_updates
    json_updates = apihelper.get_updates(self.token, offset, limit, timeout, allowed_updates)
  File "/Library/Frameworks/Python.framework/Versions/3.8/lib/python3.8/site-packages/telebot/apihelper.py", line 241, in get_updates
    return _make_request(token, method_url, params=payload)
  File "/Library/Frameworks/Python.framework/Versions/3.8/lib/python3.8/site-packages/telebot/apihelper.py", line 108, in _make_request
    json_result = _check_result(method_name, result)
  File "/Library/Frameworks/Python.framework/Versions/3.8/lib/python3.8/site-packages/telebot/apihelper.py", line 135, in _check_result
    raise ApiTelegramException(method_name, result, result_json)
telebot.apihelper.ApiTelegramException: A request to the Telegram API was unsuccessful. Error code: 409 Description: Conflict: terminated by other getUpdates request; make sure that only one bot instance is running

ERROR:TeleBot:A request to the Telegram API was unsuccessful. Error code: 409 Description: Conflict: terminated by other getUpdates request; make sure that only one bot instance is running
ERROR:TeleBot:ApiTelegramException occurred, args=('A request to the Telegram API was unsuccessful. Error code: 409 Description: Conflict: terminated by other getUpdates request; make sure that only one bot instance is running',)
Traceback (most recent call last):
  File "/Library/Frameworks/Python.framework/Versions/3.8/lib/python3.8/site-packages/telebot/util.py", line 69, in run
    task(*args, **kwargs)
  File "/Library/Frameworks/Python.framework/Versions/3.8/lib/python3.8/site-packages/telebot/__init__.py", line 285, in __retrieve_updates
    updates = self.get_updates(offset=(self.last_update_id + 1), timeout=timeout)
  File "/Library/Frameworks/Python.framework/Versions/3.8/lib/python3.8/site-packages/telebot/__init__.py", line 255, in get_updates
    json_updates = apihelper.get_updates(self.token, offset, limit, timeout, allowed_updates)
  File "/Library/Frameworks/Python.framework/Versions/3.8/lib/python3.8/site-packages/telebot/apihelper.py", line 241, in get_updates
    return _make_request(token, method_url, params=payload)
  File "/Library/Frameworks/Python.framework/Versions/3.8/lib/python3.8/site-packages/telebot/apihelper.py", line 108, in _make_request
    json_result = _check_result(method_name, result)
  File "/Library/Frameworks/Python.framework/Versions/3.8/lib/python3.8/site-packages/telebot/apihelper.py", line 135, in _check_result
    raise ApiTelegramException(method_name, result, result_json)
telebot.apihelper.ApiTelegramException: A request to the Telegram API was unsuccessful. Error code: 409 Description: Conflict: terminated by other getUpdates request; make sure that only one bot instance is running

ERROR:TeleBot:A request to the Telegram API was unsuccessful. Error code: 409 Description: Conflict: terminated by other getUpdates request; make sure that only one bot instance is running
WARNING:root:WARNING with welcome2
ERROR:root:ERROR with welcome2
CRITICAL:root:CRITICAL with welcome2
ERROR:TeleBot:ReadTimeout occurred, args=(ReadTimeoutError("HTTPSConnectionPool(host='api.telegram.org', port=443): Read timed out. (read timeout=3.5)"),)
Traceback (most recent call last):
  File "/Library/Frameworks/Python.framework/Versions/3.8/lib/python3.8/site-packages/urllib3/connectionpool.py", line 381, in _make_request
    self._validate_conn(conn)
  File "/Library/Frameworks/Python.framework/Versions/3.8/lib/python3.8/site-packages/urllib3/connectionpool.py", line 978, in _validate_conn
    conn.connect()
  File "/Library/Frameworks/Python.framework/Versions/3.8/lib/python3.8/site-packages/urllib3/connection.py", line 362, in connect
    self.sock = ssl_wrap_socket(
  File "/Library/Frameworks/Python.framework/Versions/3.8/lib/python3.8/site-packages/urllib3/util/ssl_.py", line 384, in ssl_wrap_socket
    return context.wrap_socket(sock, server_hostname=server_hostname)
  File "/Library/Frameworks/Python.framework/Versions/3.8/lib/python3.8/ssl.py", line 500, in wrap_socket
    return self.sslsocket_class._create(
  File "/Library/Frameworks/Python.framework/Versions/3.8/lib/python3.8/ssl.py", line 1040, in _create
    self.do_handshake()
  File "/Library/Frameworks/Python.framework/Versions/3.8/lib/python3.8/ssl.py", line 1309, in do_handshake
    self._sslobj.do_handshake()
socket.timeout: _ssl.c:1107: The handshake operation timed out

During handling of the above exception, another exception occurred:

Traceback (most recent call last):
  File "/Library/Frameworks/Python.framework/Versions/3.8/lib/python3.8/site-packages/requests/adapters.py", line 439, in send
    resp = conn.urlopen(
  File "/Library/Frameworks/Python.framework/Versions/3.8/lib/python3.8/site-packages/urllib3/connectionpool.py", line 726, in urlopen
    retries = retries.increment(
  File "/Library/Frameworks/Python.framework/Versions/3.8/lib/python3.8/site-packages/urllib3/util/retry.py", line 403, in increment
    raise six.reraise(type(error), error, _stacktrace)
  File "/Library/Frameworks/Python.framework/Versions/3.8/lib/python3.8/site-packages/urllib3/packages/six.py", line 735, in reraise
    raise value
  File "/Library/Frameworks/Python.framework/Versions/3.8/lib/python3.8/site-packages/urllib3/connectionpool.py", line 670, in urlopen
    httplib_response = self._make_request(
  File "/Library/Frameworks/Python.framework/Versions/3.8/lib/python3.8/site-packages/urllib3/connectionpool.py", line 384, in _make_request
    self._raise_timeout(err=e, url=url, timeout_value=conn.timeout)
  File "/Library/Frameworks/Python.framework/Versions/3.8/lib/python3.8/site-packages/urllib3/connectionpool.py", line 335, in _raise_timeout
    raise ReadTimeoutError(
urllib3.exceptions.ReadTimeoutError: HTTPSConnectionPool(host='api.telegram.org', port=443): Read timed out. (read timeout=3.5)

During handling of the above exception, another exception occurred:

Traceback (most recent call last):
  File "/Library/Frameworks/Python.framework/Versions/3.8/lib/python3.8/site-packages/telebot/util.py", line 69, in run
    task(*args, **kwargs)
  File "/Library/Frameworks/Python.framework/Versions/3.8/lib/python3.8/site-packages/telebot/__init__.py", line 285, in __retrieve_updates
    updates = self.get_updates(offset=(self.last_update_id + 1), timeout=timeout)
  File "/Library/Frameworks/Python.framework/Versions/3.8/lib/python3.8/site-packages/telebot/__init__.py", line 255, in get_updates
    json_updates = apihelper.get_updates(self.token, offset, limit, timeout, allowed_updates)
  File "/Library/Frameworks/Python.framework/Versions/3.8/lib/python3.8/site-packages/telebot/apihelper.py", line 241, in get_updates
    return _make_request(token, method_url, params=payload)
  File "/Library/Frameworks/Python.framework/Versions/3.8/lib/python3.8/site-packages/telebot/apihelper.py", line 102, in _make_request
    result = _get_req_session().request(
  File "/Library/Frameworks/Python.framework/Versions/3.8/lib/python3.8/site-packages/requests/sessions.py", line 530, in request
    resp = self.send(prep, **send_kwargs)
  File "/Library/Frameworks/Python.framework/Versions/3.8/lib/python3.8/site-packages/requests/sessions.py", line 643, in send
    r = adapter.send(request, **kwargs)
  File "/Library/Frameworks/Python.framework/Versions/3.8/lib/python3.8/site-packages/requests/adapters.py", line 529, in send
    raise ReadTimeout(e, request=request)
requests.exceptions.ReadTimeout: HTTPSConnectionPool(host='api.telegram.org', port=443): Read timed out. (read timeout=3.5)

ERROR:TeleBot:ConnectTimeout occurred, args=(MaxRetryError("HTTPSConnectionPool(host='api.telegram.org', port=443): Max retries exceeded with url: /bot1464384408:AAErqTJrLVfAWTALp2dzgz9Jsn-EgkhUK2E/getUpdates?offset=1 (Caused by ConnectTimeoutError(<urllib3.connection.HTTPSConnection object at 0x7fd78ba21550>, 'Connection to api.telegram.org timed out. (connect timeout=3.5)'))"),)
Traceback (most recent call last):
  File "/Library/Frameworks/Python.framework/Versions/3.8/lib/python3.8/site-packages/urllib3/connection.py", line 159, in _new_conn
    conn = connection.create_connection(
  File "/Library/Frameworks/Python.framework/Versions/3.8/lib/python3.8/site-packages/urllib3/util/connection.py", line 84, in create_connection
    raise err
  File "/Library/Frameworks/Python.framework/Versions/3.8/lib/python3.8/site-packages/urllib3/util/connection.py", line 74, in create_connection
    sock.connect(sa)
socket.timeout: timed out

During handling of the above exception, another exception occurred:

Traceback (most recent call last):
  File "/Library/Frameworks/Python.framework/Versions/3.8/lib/python3.8/site-packages/urllib3/connectionpool.py", line 670, in urlopen
    httplib_response = self._make_request(
  File "/Library/Frameworks/Python.framework/Versions/3.8/lib/python3.8/site-packages/urllib3/connectionpool.py", line 381, in _make_request
    self._validate_conn(conn)
  File "/Library/Frameworks/Python.framework/Versions/3.8/lib/python3.8/site-packages/urllib3/connectionpool.py", line 978, in _validate_conn
    conn.connect()
  File "/Library/Frameworks/Python.framework/Versions/3.8/lib/python3.8/site-packages/urllib3/connection.py", line 309, in connect
    conn = self._new_conn()
  File "/Library/Frameworks/Python.framework/Versions/3.8/lib/python3.8/site-packages/urllib3/connection.py", line 164, in _new_conn
    raise ConnectTimeoutError(
urllib3.exceptions.ConnectTimeoutError: (<urllib3.connection.HTTPSConnection object at 0x7fd78ba21550>, 'Connection to api.telegram.org timed out. (connect timeout=3.5)')

During handling of the above exception, another exception occurred:

Traceback (most recent call last):
  File "/Library/Frameworks/Python.framework/Versions/3.8/lib/python3.8/site-packages/requests/adapters.py", line 439, in send
    resp = conn.urlopen(
  File "/Library/Frameworks/Python.framework/Versions/3.8/lib/python3.8/site-packages/urllib3/connectionpool.py", line 726, in urlopen
    retries = retries.increment(
  File "/Library/Frameworks/Python.framework/Versions/3.8/lib/python3.8/site-packages/urllib3/util/retry.py", line 439, in increment
    raise MaxRetryError(_pool, url, error or ResponseError(cause))
urllib3.exceptions.MaxRetryError: HTTPSConnectionPool(host='api.telegram.org', port=443): Max retries exceeded with url: /bot1464384408:AAErqTJrLVfAWTALp2dzgz9Jsn-EgkhUK2E/getUpdates?offset=1 (Caused by ConnectTimeoutError(<urllib3.connection.HTTPSConnection object at 0x7fd78ba21550>, 'Connection to api.telegram.org timed out. (connect timeout=3.5)'))

During handling of the above exception, another exception occurred:

Traceback (most recent call last):
  File "/Library/Frameworks/Python.framework/Versions/3.8/lib/python3.8/site-packages/telebot/util.py", line 69, in run
    task(*args, **kwargs)
  File "/Library/Frameworks/Python.framework/Versions/3.8/lib/python3.8/site-packages/telebot/__init__.py", line 285, in __retrieve_updates
    updates = self.get_updates(offset=(self.last_update_id + 1), timeout=timeout)
  File "/Library/Frameworks/Python.framework/Versions/3.8/lib/python3.8/site-packages/telebot/__init__.py", line 255, in get_updates
    json_updates = apihelper.get_updates(self.token, offset, limit, timeout, allowed_updates)
  File "/Library/Frameworks/Python.framework/Versions/3.8/lib/python3.8/site-packages/telebot/apihelper.py", line 241, in get_updates
    return _make_request(token, method_url, params=payload)
  File "/Library/Frameworks/Python.framework/Versions/3.8/lib/python3.8/site-packages/telebot/apihelper.py", line 102, in _make_request
    result = _get_req_session().request(
  File "/Library/Frameworks/Python.framework/Versions/3.8/lib/python3.8/site-packages/requests/sessions.py", line 530, in request
    resp = self.send(prep, **send_kwargs)
  File "/Library/Frameworks/Python.framework/Versions/3.8/lib/python3.8/site-packages/requests/sessions.py", line 643, in send
    r = adapter.send(request, **kwargs)
  File "/Library/Frameworks/Python.framework/Versions/3.8/lib/python3.8/site-packages/requests/adapters.py", line 504, in send
    raise ConnectTimeout(e, request=request)
requests.exceptions.ConnectTimeout: HTTPSConnectionPool(host='api.telegram.org', port=443): Max retries exceeded with url: /bot1464384408:AAErqTJrLVfAWTALp2dzgz9Jsn-EgkhUK2E/getUpdates?offset=1 (Caused by ConnectTimeoutError(<urllib3.connection.HTTPSConnection object at 0x7fd78ba21550>, 'Connection to api.telegram.org timed out. (connect timeout=3.5)'))

ERROR:TeleBot:ReadTimeout occurred, args=(ReadTimeoutError("HTTPSConnectionPool(host='api.telegram.org', port=443): Read timed out. (read timeout=3.5)"),)
Traceback (most recent call last):
  File "/Library/Frameworks/Python.framework/Versions/3.8/lib/python3.8/site-packages/urllib3/connectionpool.py", line 381, in _make_request
    self._validate_conn(conn)
  File "/Library/Frameworks/Python.framework/Versions/3.8/lib/python3.8/site-packages/urllib3/connectionpool.py", line 978, in _validate_conn
    conn.connect()
  File "/Library/Frameworks/Python.framework/Versions/3.8/lib/python3.8/site-packages/urllib3/connection.py", line 362, in connect
    self.sock = ssl_wrap_socket(
  File "/Library/Frameworks/Python.framework/Versions/3.8/lib/python3.8/site-packages/urllib3/util/ssl_.py", line 384, in ssl_wrap_socket
    return context.wrap_socket(sock, server_hostname=server_hostname)
  File "/Library/Frameworks/Python.framework/Versions/3.8/lib/python3.8/ssl.py", line 500, in wrap_socket
    return self.sslsocket_class._create(
  File "/Library/Frameworks/Python.framework/Versions/3.8/lib/python3.8/ssl.py", line 1040, in _create
    self.do_handshake()
  File "/Library/Frameworks/Python.framework/Versions/3.8/lib/python3.8/ssl.py", line 1309, in do_handshake
    self._sslobj.do_handshake()
socket.timeout: _ssl.c:1107: The handshake operation timed out

During handling of the above exception, another exception occurred:

Traceback (most recent call last):
  File "/Library/Frameworks/Python.framework/Versions/3.8/lib/python3.8/site-packages/requests/adapters.py", line 439, in send
    resp = conn.urlopen(
  File "/Library/Frameworks/Python.framework/Versions/3.8/lib/python3.8/site-packages/urllib3/connectionpool.py", line 726, in urlopen
    retries = retries.increment(
  File "/Library/Frameworks/Python.framework/Versions/3.8/lib/python3.8/site-packages/urllib3/util/retry.py", line 403, in increment
    raise six.reraise(type(error), error, _stacktrace)
  File "/Library/Frameworks/Python.framework/Versions/3.8/lib/python3.8/site-packages/urllib3/packages/six.py", line 735, in reraise
    raise value
  File "/Library/Frameworks/Python.framework/Versions/3.8/lib/python3.8/site-packages/urllib3/connectionpool.py", line 670, in urlopen
    httplib_response = self._make_request(
  File "/Library/Frameworks/Python.framework/Versions/3.8/lib/python3.8/site-packages/urllib3/connectionpool.py", line 384, in _make_request
    self._raise_timeout(err=e, url=url, timeout_value=conn.timeout)
  File "/Library/Frameworks/Python.framework/Versions/3.8/lib/python3.8/site-packages/urllib3/connectionpool.py", line 335, in _raise_timeout
    raise ReadTimeoutError(
urllib3.exceptions.ReadTimeoutError: HTTPSConnectionPool(host='api.telegram.org', port=443): Read timed out. (read timeout=3.5)

During handling of the above exception, another exception occurred:

Traceback (most recent call last):
  File "/Library/Frameworks/Python.framework/Versions/3.8/lib/python3.8/site-packages/telebot/util.py", line 69, in run
    task(*args, **kwargs)
  File "/Library/Frameworks/Python.framework/Versions/3.8/lib/python3.8/site-packages/telebot/__init__.py", line 285, in __retrieve_updates
    updates = self.get_updates(offset=(self.last_update_id + 1), timeout=timeout)
  File "/Library/Frameworks/Python.framework/Versions/3.8/lib/python3.8/site-packages/telebot/__init__.py", line 255, in get_updates
    json_updates = apihelper.get_updates(self.token, offset, limit, timeout, allowed_updates)
  File "/Library/Frameworks/Python.framework/Versions/3.8/lib/python3.8/site-packages/telebot/apihelper.py", line 241, in get_updates
    return _make_request(token, method_url, params=payload)
  File "/Library/Frameworks/Python.framework/Versions/3.8/lib/python3.8/site-packages/telebot/apihelper.py", line 102, in _make_request
    result = _get_req_session().request(
  File "/Library/Frameworks/Python.framework/Versions/3.8/lib/python3.8/site-packages/requests/sessions.py", line 530, in request
    resp = self.send(prep, **send_kwargs)
  File "/Library/Frameworks/Python.framework/Versions/3.8/lib/python3.8/site-packages/requests/sessions.py", line 643, in send
    r = adapter.send(request, **kwargs)
  File "/Library/Frameworks/Python.framework/Versions/3.8/lib/python3.8/site-packages/requests/adapters.py", line 529, in send
    raise ReadTimeout(e, request=request)
requests.exceptions.ReadTimeout: HTTPSConnectionPool(host='api.telegram.org', port=443): Read timed out. (read timeout=3.5)

ERROR:TeleBot:ReadTimeout occurred, args=(ReadTimeoutError("HTTPSConnectionPool(host='api.telegram.org', port=443): Read timed out. (read timeout=3.5)"),)
Traceback (most recent call last):
  File "/Library/Frameworks/Python.framework/Versions/3.8/lib/python3.8/site-packages/urllib3/connectionpool.py", line 381, in _make_request
    self._validate_conn(conn)
  File "/Library/Frameworks/Python.framework/Versions/3.8/lib/python3.8/site-packages/urllib3/connectionpool.py", line 978, in _validate_conn
    conn.connect()
  File "/Library/Frameworks/Python.framework/Versions/3.8/lib/python3.8/site-packages/urllib3/connection.py", line 362, in connect
    self.sock = ssl_wrap_socket(
  File "/Library/Frameworks/Python.framework/Versions/3.8/lib/python3.8/site-packages/urllib3/util/ssl_.py", line 384, in ssl_wrap_socket
    return context.wrap_socket(sock, server_hostname=server_hostname)
  File "/Library/Frameworks/Python.framework/Versions/3.8/lib/python3.8/ssl.py", line 500, in wrap_socket
    return self.sslsocket_class._create(
  File "/Library/Frameworks/Python.framework/Versions/3.8/lib/python3.8/ssl.py", line 1040, in _create
    self.do_handshake()
  File "/Library/Frameworks/Python.framework/Versions/3.8/lib/python3.8/ssl.py", line 1309, in do_handshake
    self._sslobj.do_handshake()
socket.timeout: _ssl.c:1107: The handshake operation timed out

During handling of the above exception, another exception occurred:

Traceback (most recent call last):
  File "/Library/Frameworks/Python.framework/Versions/3.8/lib/python3.8/site-packages/requests/adapters.py", line 439, in send
    resp = conn.urlopen(
  File "/Library/Frameworks/Python.framework/Versions/3.8/lib/python3.8/site-packages/urllib3/connectionpool.py", line 726, in urlopen
    retries = retries.increment(
  File "/Library/Frameworks/Python.framework/Versions/3.8/lib/python3.8/site-packages/urllib3/util/retry.py", line 403, in increment
    raise six.reraise(type(error), error, _stacktrace)
  File "/Library/Frameworks/Python.framework/Versions/3.8/lib/python3.8/site-packages/urllib3/packages/six.py", line 735, in reraise
    raise value
  File "/Library/Frameworks/Python.framework/Versions/3.8/lib/python3.8/site-packages/urllib3/connectionpool.py", line 670, in urlopen
    httplib_response = self._make_request(
  File "/Library/Frameworks/Python.framework/Versions/3.8/lib/python3.8/site-packages/urllib3/connectionpool.py", line 384, in _make_request
    self._raise_timeout(err=e, url=url, timeout_value=conn.timeout)
  File "/Library/Frameworks/Python.framework/Versions/3.8/lib/python3.8/site-packages/urllib3/connectionpool.py", line 335, in _raise_timeout
    raise ReadTimeoutError(
urllib3.exceptions.ReadTimeoutError: HTTPSConnectionPool(host='api.telegram.org', port=443): Read timed out. (read timeout=3.5)

During handling of the above exception, another exception occurred:

Traceback (most recent call last):
  File "/Library/Frameworks/Python.framework/Versions/3.8/lib/python3.8/site-packages/telebot/util.py", line 69, in run
    task(*args, **kwargs)
  File "/Library/Frameworks/Python.framework/Versions/3.8/lib/python3.8/site-packages/telebot/__init__.py", line 285, in __retrieve_updates
    updates = self.get_updates(offset=(self.last_update_id + 1), timeout=timeout)
  File "/Library/Frameworks/Python.framework/Versions/3.8/lib/python3.8/site-packages/telebot/__init__.py", line 255, in get_updates
    json_updates = apihelper.get_updates(self.token, offset, limit, timeout, allowed_updates)
  File "/Library/Frameworks/Python.framework/Versions/3.8/lib/python3.8/site-packages/telebot/apihelper.py", line 241, in get_updates
    return _make_request(token, method_url, params=payload)
  File "/Library/Frameworks/Python.framework/Versions/3.8/lib/python3.8/site-packages/telebot/apihelper.py", line 102, in _make_request
    result = _get_req_session().request(
  File "/Library/Frameworks/Python.framework/Versions/3.8/lib/python3.8/site-packages/requests/sessions.py", line 530, in request
    resp = self.send(prep, **send_kwargs)
  File "/Library/Frameworks/Python.framework/Versions/3.8/lib/python3.8/site-packages/requests/sessions.py", line 643, in send
    r = adapter.send(request, **kwargs)
  File "/Library/Frameworks/Python.framework/Versions/3.8/lib/python3.8/site-packages/requests/adapters.py", line 529, in send
    raise ReadTimeout(e, request=request)
requests.exceptions.ReadTimeout: HTTPSConnectionPool(host='api.telegram.org', port=443): Read timed out. (read timeout=3.5)

ERROR:TeleBot:ReadTimeout occurred, args=(ReadTimeoutError("HTTPSConnectionPool(host='api.telegram.org', port=443): Read timed out. (read timeout=3.5)"),)
Traceback (most recent call last):
  File "/Library/Frameworks/Python.framework/Versions/3.8/lib/python3.8/site-packages/urllib3/connectionpool.py", line 381, in _make_request
    self._validate_conn(conn)
  File "/Library/Frameworks/Python.framework/Versions/3.8/lib/python3.8/site-packages/urllib3/connectionpool.py", line 978, in _validate_conn
    conn.connect()
  File "/Library/Frameworks/Python.framework/Versions/3.8/lib/python3.8/site-packages/urllib3/connection.py", line 362, in connect
    self.sock = ssl_wrap_socket(
  File "/Library/Frameworks/Python.framework/Versions/3.8/lib/python3.8/site-packages/urllib3/util/ssl_.py", line 384, in ssl_wrap_socket
    return context.wrap_socket(sock, server_hostname=server_hostname)
  File "/Library/Frameworks/Python.framework/Versions/3.8/lib/python3.8/ssl.py", line 500, in wrap_socket
    return self.sslsocket_class._create(
  File "/Library/Frameworks/Python.framework/Versions/3.8/lib/python3.8/ssl.py", line 1040, in _create
    self.do_handshake()
  File "/Library/Frameworks/Python.framework/Versions/3.8/lib/python3.8/ssl.py", line 1309, in do_handshake
    self._sslobj.do_handshake()
socket.timeout: _ssl.c:1107: The handshake operation timed out

During handling of the above exception, another exception occurred:

Traceback (most recent call last):
  File "/Library/Frameworks/Python.framework/Versions/3.8/lib/python3.8/site-packages/requests/adapters.py", line 439, in send
    resp = conn.urlopen(
  File "/Library/Frameworks/Python.framework/Versions/3.8/lib/python3.8/site-packages/urllib3/connectionpool.py", line 726, in urlopen
    retries = retries.increment(
  File "/Library/Frameworks/Python.framework/Versions/3.8/lib/python3.8/site-packages/urllib3/util/retry.py", line 403, in increment
    raise six.reraise(type(error), error, _stacktrace)
  File "/Library/Frameworks/Python.framework/Versions/3.8/lib/python3.8/site-packages/urllib3/packages/six.py", line 735, in reraise
    raise value
  File "/Library/Frameworks/Python.framework/Versions/3.8/lib/python3.8/site-packages/urllib3/connectionpool.py", line 670, in urlopen
    httplib_response = self._make_request(
  File "/Library/Frameworks/Python.framework/Versions/3.8/lib/python3.8/site-packages/urllib3/connectionpool.py", line 384, in _make_request
    self._raise_timeout(err=e, url=url, timeout_value=conn.timeout)
  File "/Library/Frameworks/Python.framework/Versions/3.8/lib/python3.8/site-packages/urllib3/connectionpool.py", line 335, in _raise_timeout
    raise ReadTimeoutError(
urllib3.exceptions.ReadTimeoutError: HTTPSConnectionPool(host='api.telegram.org', port=443): Read timed out. (read timeout=3.5)

During handling of the above exception, another exception occurred:

Traceback (most recent call last):
  File "/Library/Frameworks/Python.framework/Versions/3.8/lib/python3.8/site-packages/telebot/util.py", line 69, in run
    task(*args, **kwargs)
  File "/Library/Frameworks/Python.framework/Versions/3.8/lib/python3.8/site-packages/telebot/__init__.py", line 285, in __retrieve_updates
    updates = self.get_updates(offset=(self.last_update_id + 1), timeout=timeout)
  File "/Library/Frameworks/Python.framework/Versions/3.8/lib/python3.8/site-packages/telebot/__init__.py", line 255, in get_updates
    json_updates = apihelper.get_updates(self.token, offset, limit, timeout, allowed_updates)
  File "/Library/Frameworks/Python.framework/Versions/3.8/lib/python3.8/site-packages/telebot/apihelper.py", line 241, in get_updates
    return _make_request(token, method_url, params=payload)
  File "/Library/Frameworks/Python.framework/Versions/3.8/lib/python3.8/site-packages/telebot/apihelper.py", line 102, in _make_request
    result = _get_req_session().request(
  File "/Library/Frameworks/Python.framework/Versions/3.8/lib/python3.8/site-packages/requests/sessions.py", line 530, in request
    resp = self.send(prep, **send_kwargs)
  File "/Library/Frameworks/Python.framework/Versions/3.8/lib/python3.8/site-packages/requests/sessions.py", line 643, in send
    r = adapter.send(request, **kwargs)
  File "/Library/Frameworks/Python.framework/Versions/3.8/lib/python3.8/site-packages/requests/adapters.py", line 529, in send
    raise ReadTimeout(e, request=request)
requests.exceptions.ReadTimeout: HTTPSConnectionPool(host='api.telegram.org', port=443): Read timed out. (read timeout=3.5)

WARNING:root:WARNING with welcome2
ERROR:root:ERROR with welcome2
CRITICAL:root:CRITICAL with welcome2
WARNING:root:WARNING with lalala
ERROR:root:ERROR with lalala
CRITICAL:root:CRITICAL with lalala
WARNING:root:WARNING with callback_inline
ERROR:root:ERROR with callback_inline
CRITICAL:root:CRITICAL with callback_inline
WARNING:root:WARNING with lalala
ERROR:root:ERROR with lalala
CRITICAL:root:CRITICAL with lalala
WARNING:root:WARNING with lalala
ERROR:root:ERROR with lalala
CRITICAL:root:CRITICAL with lalala
WARNING:root:WARNING with lalala
ERROR:root:ERROR with lalala
CRITICAL:root:CRITICAL with lalala
WARNING:root:WARNING with lalala
ERROR:root:ERROR with lalala
CRITICAL:root:CRITICAL with lalala
WARNING:root:WARNING with lalala
ERROR:root:ERROR with lalala
CRITICAL:root:CRITICAL with lalala
WARNING:root:WARNING with callback_inline
ERROR:root:ERROR with callback_inline
CRITICAL:root:CRITICAL with callback_inline
WARNING:root:WARNING with callback_inline
ERROR:root:ERROR with callback_inline
CRITICAL:root:CRITICAL with callback_inline
